[2023-10-26T10:09:35.412+0000] {taskinstance.py:1157} INFO - Dependencies all met for dep_context=non-requeueable deps ti=<TaskInstance: read_db_and_save_local.read_db scheduled__2023-10-24T00:00:00+00:00 [queued]>
[2023-10-26T10:09:35.420+0000] {taskinstance.py:1157} INFO - Dependencies all met for dep_context=requeueable deps ti=<TaskInstance: read_db_and_save_local.read_db scheduled__2023-10-24T00:00:00+00:00 [queued]>
[2023-10-26T10:09:35.420+0000] {taskinstance.py:1359} INFO - Starting attempt 1 of 1
[2023-10-26T10:09:35.433+0000] {taskinstance.py:1380} INFO - Executing <Task(PythonOperator): read_db> on 2023-10-24 00:00:00+00:00
[2023-10-26T10:09:35.437+0000] {standard_task_runner.py:57} INFO - Started process 152 to run task
[2023-10-26T10:09:35.441+0000] {standard_task_runner.py:84} INFO - Running: ['***', 'tasks', 'run', 'read_db_and_save_local', 'read_db', 'scheduled__2023-10-24T00:00:00+00:00', '--job-id', '8', '--raw', '--subdir', 'DAGS_FOLDER/read_db_and_save_local.py', '--cfg-path', '/tmp/tmp62qph373']
[2023-10-26T10:09:35.443+0000] {standard_task_runner.py:85} INFO - Job 8: Subtask read_db
[2023-10-26T10:09:35.477+0000] {task_command.py:415} INFO - Running <TaskInstance: read_db_and_save_local.read_db scheduled__2023-10-24T00:00:00+00:00 [running]> on host 88a410f69adf
[2023-10-26T10:09:35.531+0000] {taskinstance.py:1660} INFO - Exporting env vars: AIRFLOW_CTX_DAG_EMAIL='***@example.com' AIRFLOW_CTX_DAG_OWNER='***' AIRFLOW_CTX_DAG_ID='read_db_and_save_local' AIRFLOW_CTX_TASK_ID='read_db' AIRFLOW_CTX_EXECUTION_DATE='2023-10-24T00:00:00+00:00' AIRFLOW_CTX_TRY_NUMBER='1' AIRFLOW_CTX_DAG_RUN_ID='scheduled__2023-10-24T00:00:00+00:00'
[2023-10-26T10:09:35.540+0000] {base.py:73} INFO - Using connection ID 'mydb' for task execution.
[2023-10-26T10:09:35.574+0000] {taskinstance.py:1935} ERROR - Task failed with exception
Traceback (most recent call last):
  File "/home/airflow/.local/lib/python3.8/site-packages/airflow/operators/python.py", line 192, in execute
    return_value = self.execute_callable()
  File "/home/airflow/.local/lib/python3.8/site-packages/airflow/operators/python.py", line 209, in execute_callable
    return self.python_callable(*self.op_args, **self.op_kwargs)
  File "/opt/airflow/dags/read_db_and_save_local.py", line 21, in reading_data
    cursor.execute(request)
  File "/home/airflow/.local/lib/python3.8/site-packages/MySQLdb/cursors.py", line 179, in execute
    res = self._query(mogrified_query)
  File "/home/airflow/.local/lib/python3.8/site-packages/MySQLdb/cursors.py", line 330, in _query
    db.query(q)
  File "/home/airflow/.local/lib/python3.8/site-packages/MySQLdb/connections.py", line 255, in query
    _mysql.connection.query(self, query)
MySQLdb.ProgrammingError: (1146, "Table 'homestead.Customer' doesn't exist")
[2023-10-26T10:09:35.583+0000] {taskinstance.py:1398} INFO - Marking task as FAILED. dag_id=read_db_and_save_local, task_id=read_db, execution_date=20231024T000000, start_date=20231026T100935, end_date=20231026T100935
[2023-10-26T10:09:35.593+0000] {warnings.py:109} WARNING - /home/***/.local/lib/python3.8/site-packages/***/utils/email.py:154: RemovedInAirflow3Warning: Fetching SMTP credentials from configuration variables will be deprecated in a future release. Please set credentials using a connection instead.
  send_mime_email(e_from=mail_from, e_to=recipients, mime_msg=msg, conn_id=conn_id, dryrun=dryrun)

[2023-10-26T10:09:35.594+0000] {configuration.py:1063} WARNING - section/key [smtp/smtp_user] not found in config
[2023-10-26T10:09:35.594+0000] {email.py:270} INFO - Email alerting: attempt 1
[2023-10-26T10:09:35.600+0000] {configuration.py:1063} WARNING - section/key [smtp/smtp_user] not found in config
[2023-10-26T10:09:35.600+0000] {email.py:270} INFO - Email alerting: attempt 1
[2023-10-26T10:09:35.601+0000] {taskinstance.py:2005} ERROR - Failed to send email to: ['***@example.com']
Traceback (most recent call last):
  File "/home/airflow/.local/lib/python3.8/site-packages/airflow/models/taskinstance.py", line 1516, in _run_raw_task
    self._execute_task_with_callbacks(context, test_mode, session=session)
  File "/home/airflow/.local/lib/python3.8/site-packages/airflow/models/taskinstance.py", line 1679, in _execute_task_with_callbacks
    result = self._execute_task(context, task_orig)
  File "/home/airflow/.local/lib/python3.8/site-packages/airflow/models/taskinstance.py", line 1742, in _execute_task
    result = execute_callable(context=context, **execute_callable_kwargs)
  File "/home/airflow/.local/lib/python3.8/site-packages/airflow/operators/python.py", line 192, in execute
    return_value = self.execute_callable()
  File "/home/airflow/.local/lib/python3.8/site-packages/airflow/operators/python.py", line 209, in execute_callable
    return self.python_callable(*self.op_args, **self.op_kwargs)
  File "/opt/airflow/dags/read_db_and_save_local.py", line 21, in reading_data
    cursor.execute(request)
  File "/home/airflow/.local/lib/python3.8/site-packages/MySQLdb/cursors.py", line 179, in execute
    res = self._query(mogrified_query)
  File "/home/airflow/.local/lib/python3.8/site-packages/MySQLdb/cursors.py", line 330, in _query
    db.query(q)
  File "/home/airflow/.local/lib/python3.8/site-packages/MySQLdb/connections.py", line 255, in query
    _mysql.connection.query(self, query)
MySQLdb.ProgrammingError: (1146, "Table 'homestead.Customer' doesn't exist")

During handling of the above exception, another exception occurred:

Traceback (most recent call last):
  File "/home/airflow/.local/lib/python3.8/site-packages/airflow/models/taskinstance.py", line 2418, in email_alert
    send_email(task.email, subject, html_content)
  File "/home/airflow/.local/lib/python3.8/site-packages/airflow/utils/email.py", line 80, in send_email
    return backend(
  File "/home/airflow/.local/lib/python3.8/site-packages/airflow/utils/email.py", line 154, in send_email_smtp
    send_mime_email(e_from=mail_from, e_to=recipients, mime_msg=msg, conn_id=conn_id, dryrun=dryrun)
  File "/home/airflow/.local/lib/python3.8/site-packages/airflow/utils/email.py", line 272, in send_mime_email
    smtp_conn = _get_smtp_connection(smtp_host, smtp_port, smtp_timeout, smtp_ssl)
  File "/home/airflow/.local/lib/python3.8/site-packages/airflow/utils/email.py", line 317, in _get_smtp_connection
    return smtplib.SMTP(host=host, port=port, timeout=timeout)
  File "/usr/local/lib/python3.8/smtplib.py", line 255, in __init__
    (code, msg) = self.connect(host, port)
  File "/usr/local/lib/python3.8/smtplib.py", line 339, in connect
    self.sock = self._get_socket(host, port, self.timeout)
  File "/usr/local/lib/python3.8/smtplib.py", line 310, in _get_socket
    return socket.create_connection((host, port), timeout,
  File "/usr/local/lib/python3.8/socket.py", line 808, in create_connection
    raise err
  File "/usr/local/lib/python3.8/socket.py", line 796, in create_connection
    sock.connect(sa)
OSError: [Errno 99] Cannot assign requested address

During handling of the above exception, another exception occurred:

Traceback (most recent call last):
  File "/home/airflow/.local/lib/python3.8/site-packages/airflow/models/taskinstance.py", line 2003, in handle_failure
    self.email_alert(error, task)
  File "/home/airflow/.local/lib/python3.8/site-packages/airflow/models/taskinstance.py", line 2420, in email_alert
    send_email(task.email, subject, html_content_err)
  File "/home/airflow/.local/lib/python3.8/site-packages/airflow/utils/email.py", line 80, in send_email
    return backend(
  File "/home/airflow/.local/lib/python3.8/site-packages/airflow/utils/email.py", line 154, in send_email_smtp
    send_mime_email(e_from=mail_from, e_to=recipients, mime_msg=msg, conn_id=conn_id, dryrun=dryrun)
  File "/home/airflow/.local/lib/python3.8/site-packages/airflow/utils/email.py", line 272, in send_mime_email
    smtp_conn = _get_smtp_connection(smtp_host, smtp_port, smtp_timeout, smtp_ssl)
  File "/home/airflow/.local/lib/python3.8/site-packages/airflow/utils/email.py", line 317, in _get_smtp_connection
    return smtplib.SMTP(host=host, port=port, timeout=timeout)
  File "/usr/local/lib/python3.8/smtplib.py", line 255, in __init__
    (code, msg) = self.connect(host, port)
  File "/usr/local/lib/python3.8/smtplib.py", line 339, in connect
    self.sock = self._get_socket(host, port, self.timeout)
  File "/usr/local/lib/python3.8/smtplib.py", line 310, in _get_socket
    return socket.create_connection((host, port), timeout,
  File "/usr/local/lib/python3.8/socket.py", line 808, in create_connection
    raise err
  File "/usr/local/lib/python3.8/socket.py", line 796, in create_connection
    sock.connect(sa)
OSError: [Errno 99] Cannot assign requested address
[2023-10-26T10:09:35.757+0000] {standard_task_runner.py:104} ERROR - Failed to execute job 8 for task read_db ((1146, "Table 'homestead.Customer' doesn't exist"); 152)
[2023-10-26T10:09:35.773+0000] {local_task_job_runner.py:228} INFO - Task exited with return code 1
[2023-10-26T10:09:35.789+0000] {taskinstance.py:2776} INFO - 0 downstream tasks scheduled from follow-on schedule check
