[2023-10-26T10:44:07.616+0000] {taskinstance.py:1157} INFO - Dependencies all met for dep_context=non-requeueable deps ti=<TaskInstance: read_db_and_save_local.save_csv scheduled__2023-10-25T00:00:00+00:00 [queued]>
[2023-10-26T10:44:07.624+0000] {taskinstance.py:1157} INFO - Dependencies all met for dep_context=requeueable deps ti=<TaskInstance: read_db_and_save_local.save_csv scheduled__2023-10-25T00:00:00+00:00 [queued]>
[2023-10-26T10:44:07.625+0000] {taskinstance.py:1359} INFO - Starting attempt 7 of 7
[2023-10-26T10:44:07.636+0000] {taskinstance.py:1380} INFO - Executing <Task(PythonOperator): save_csv> on 2023-10-25 00:00:00+00:00
[2023-10-26T10:44:07.640+0000] {standard_task_runner.py:57} INFO - Started process 215 to run task
[2023-10-26T10:44:07.642+0000] {standard_task_runner.py:84} INFO - Running: ['***', 'tasks', 'run', 'read_db_and_save_local', 'save_csv', 'scheduled__2023-10-25T00:00:00+00:00', '--job-id', '29', '--raw', '--subdir', 'DAGS_FOLDER/read_db_and_save_local.py', '--cfg-path', '/tmp/tmpoax8geic']
[2023-10-26T10:44:07.644+0000] {standard_task_runner.py:85} INFO - Job 29: Subtask save_csv
[2023-10-26T10:44:07.681+0000] {task_command.py:415} INFO - Running <TaskInstance: read_db_and_save_local.save_csv scheduled__2023-10-25T00:00:00+00:00 [running]> on host 88a410f69adf
[2023-10-26T10:44:07.852+0000] {taskinstance.py:1660} INFO - Exporting env vars: AIRFLOW_CTX_DAG_EMAIL='***@example.com' AIRFLOW_CTX_DAG_OWNER='***' AIRFLOW_CTX_DAG_ID='read_db_and_save_local' AIRFLOW_CTX_TASK_ID='save_csv' AIRFLOW_CTX_EXECUTION_DATE='2023-10-25T00:00:00+00:00' AIRFLOW_CTX_TRY_NUMBER='7' AIRFLOW_CTX_DAG_RUN_ID='scheduled__2023-10-25T00:00:00+00:00'
[2023-10-26T10:44:07.854+0000] {taskinstance.py:1935} ERROR - Task failed with exception
Traceback (most recent call last):
  File "/home/airflow/.local/lib/python3.8/site-packages/airflow/operators/python.py", line 192, in execute
    return_value = self.execute_callable()
  File "/home/airflow/.local/lib/python3.8/site-packages/airflow/operators/python.py", line 209, in execute_callable
    return self.python_callable(*self.op_args, **self.op_kwargs)
  File "/opt/airflow/dags/read_db_and_save_local.py", line 28, in save_to_csv
    df = pd.DataFrame(sources,columns=[desc[0] for desc in cursor.description])
NameError: name 'sources' is not defined
[2023-10-26T10:44:07.864+0000] {taskinstance.py:1398} INFO - Marking task as FAILED. dag_id=read_db_and_save_local, task_id=save_csv, execution_date=20231025T000000, start_date=20231026T104407, end_date=20231026T104407
[2023-10-26T10:44:07.875+0000] {warnings.py:109} WARNING - /home/***/.local/lib/python3.8/site-packages/***/utils/email.py:154: RemovedInAirflow3Warning: Fetching SMTP credentials from configuration variables will be deprecated in a future release. Please set credentials using a connection instead.
  send_mime_email(e_from=mail_from, e_to=recipients, mime_msg=msg, conn_id=conn_id, dryrun=dryrun)

[2023-10-26T10:44:07.875+0000] {configuration.py:1063} WARNING - section/key [smtp/smtp_user] not found in config
[2023-10-26T10:44:07.876+0000] {email.py:270} INFO - Email alerting: attempt 1
[2023-10-26T10:44:07.882+0000] {configuration.py:1063} WARNING - section/key [smtp/smtp_user] not found in config
[2023-10-26T10:44:07.883+0000] {email.py:270} INFO - Email alerting: attempt 1
[2023-10-26T10:44:07.883+0000] {taskinstance.py:2005} ERROR - Failed to send email to: ['***@example.com']
Traceback (most recent call last):
  File "/home/airflow/.local/lib/python3.8/site-packages/airflow/models/taskinstance.py", line 1516, in _run_raw_task
    self._execute_task_with_callbacks(context, test_mode, session=session)
  File "/home/airflow/.local/lib/python3.8/site-packages/airflow/models/taskinstance.py", line 1679, in _execute_task_with_callbacks
    result = self._execute_task(context, task_orig)
  File "/home/airflow/.local/lib/python3.8/site-packages/airflow/models/taskinstance.py", line 1742, in _execute_task
    result = execute_callable(context=context, **execute_callable_kwargs)
  File "/home/airflow/.local/lib/python3.8/site-packages/airflow/operators/python.py", line 192, in execute
    return_value = self.execute_callable()
  File "/home/airflow/.local/lib/python3.8/site-packages/airflow/operators/python.py", line 209, in execute_callable
    return self.python_callable(*self.op_args, **self.op_kwargs)
  File "/opt/airflow/dags/read_db_and_save_local.py", line 28, in save_to_csv
    df = pd.DataFrame(sources,columns=[desc[0] for desc in cursor.description])
NameError: name 'sources' is not defined

During handling of the above exception, another exception occurred:

Traceback (most recent call last):
  File "/home/airflow/.local/lib/python3.8/site-packages/airflow/models/taskinstance.py", line 2418, in email_alert
    send_email(task.email, subject, html_content)
  File "/home/airflow/.local/lib/python3.8/site-packages/airflow/utils/email.py", line 80, in send_email
    return backend(
  File "/home/airflow/.local/lib/python3.8/site-packages/airflow/utils/email.py", line 154, in send_email_smtp
    send_mime_email(e_from=mail_from, e_to=recipients, mime_msg=msg, conn_id=conn_id, dryrun=dryrun)
  File "/home/airflow/.local/lib/python3.8/site-packages/airflow/utils/email.py", line 272, in send_mime_email
    smtp_conn = _get_smtp_connection(smtp_host, smtp_port, smtp_timeout, smtp_ssl)
  File "/home/airflow/.local/lib/python3.8/site-packages/airflow/utils/email.py", line 317, in _get_smtp_connection
    return smtplib.SMTP(host=host, port=port, timeout=timeout)
  File "/usr/local/lib/python3.8/smtplib.py", line 255, in __init__
    (code, msg) = self.connect(host, port)
  File "/usr/local/lib/python3.8/smtplib.py", line 339, in connect
    self.sock = self._get_socket(host, port, self.timeout)
  File "/usr/local/lib/python3.8/smtplib.py", line 310, in _get_socket
    return socket.create_connection((host, port), timeout,
  File "/usr/local/lib/python3.8/socket.py", line 808, in create_connection
    raise err
  File "/usr/local/lib/python3.8/socket.py", line 796, in create_connection
    sock.connect(sa)
OSError: [Errno 99] Cannot assign requested address

During handling of the above exception, another exception occurred:

Traceback (most recent call last):
  File "/home/airflow/.local/lib/python3.8/site-packages/airflow/models/taskinstance.py", line 2003, in handle_failure
    self.email_alert(error, task)
  File "/home/airflow/.local/lib/python3.8/site-packages/airflow/models/taskinstance.py", line 2420, in email_alert
    send_email(task.email, subject, html_content_err)
  File "/home/airflow/.local/lib/python3.8/site-packages/airflow/utils/email.py", line 80, in send_email
    return backend(
  File "/home/airflow/.local/lib/python3.8/site-packages/airflow/utils/email.py", line 154, in send_email_smtp
    send_mime_email(e_from=mail_from, e_to=recipients, mime_msg=msg, conn_id=conn_id, dryrun=dryrun)
  File "/home/airflow/.local/lib/python3.8/site-packages/airflow/utils/email.py", line 272, in send_mime_email
    smtp_conn = _get_smtp_connection(smtp_host, smtp_port, smtp_timeout, smtp_ssl)
  File "/home/airflow/.local/lib/python3.8/site-packages/airflow/utils/email.py", line 317, in _get_smtp_connection
    return smtplib.SMTP(host=host, port=port, timeout=timeout)
  File "/usr/local/lib/python3.8/smtplib.py", line 255, in __init__
    (code, msg) = self.connect(host, port)
  File "/usr/local/lib/python3.8/smtplib.py", line 339, in connect
    self.sock = self._get_socket(host, port, self.timeout)
  File "/usr/local/lib/python3.8/smtplib.py", line 310, in _get_socket
    return socket.create_connection((host, port), timeout,
  File "/usr/local/lib/python3.8/socket.py", line 808, in create_connection
    raise err
  File "/usr/local/lib/python3.8/socket.py", line 796, in create_connection
    sock.connect(sa)
OSError: [Errno 99] Cannot assign requested address
[2023-10-26T10:44:07.894+0000] {standard_task_runner.py:104} ERROR - Failed to execute job 29 for task save_csv (name 'sources' is not defined; 215)
[2023-10-26T10:44:07.936+0000] {local_task_job_runner.py:228} INFO - Task exited with return code 1
[2023-10-26T10:44:07.952+0000] {taskinstance.py:2776} INFO - 0 downstream tasks scheduled from follow-on schedule check
