[2023-09-16T04:50:33.114+0000] {taskinstance.py:1157} INFO - Dependencies all met for dep_context=non-requeueable deps ti=<TaskInstance: branching_example.generate_random_number manual__2023-09-16T04:50:32.158743+00:00 [queued]>
[2023-09-16T04:50:33.120+0000] {taskinstance.py:1157} INFO - Dependencies all met for dep_context=requeueable deps ti=<TaskInstance: branching_example.generate_random_number manual__2023-09-16T04:50:32.158743+00:00 [queued]>
[2023-09-16T04:50:33.120+0000] {taskinstance.py:1359} INFO - Starting attempt 1 of 1
[2023-09-16T04:50:33.132+0000] {taskinstance.py:1380} INFO - Executing <Task(PythonOperator): generate_random_number> on 2023-09-16 04:50:32.158743+00:00
[2023-09-16T04:50:33.136+0000] {standard_task_runner.py:57} INFO - Started process 1900 to run task
[2023-09-16T04:50:33.138+0000] {standard_task_runner.py:84} INFO - Running: ['***', 'tasks', 'run', 'branching_example', 'generate_random_number', 'manual__2023-09-16T04:50:32.158743+00:00', '--job-id', '57', '--raw', '--subdir', 'DAGS_FOLDER/task.py', '--cfg-path', '/tmp/tmpg1k536xa']
[2023-09-16T04:50:33.139+0000] {standard_task_runner.py:85} INFO - Job 57: Subtask generate_random_number
[2023-09-16T04:50:33.171+0000] {task_command.py:415} INFO - Running <TaskInstance: branching_example.generate_random_number manual__2023-09-16T04:50:32.158743+00:00 [running]> on host 63e9c8165189
[2023-09-16T04:50:33.221+0000] {taskinstance.py:1660} INFO - Exporting env vars: AIRFLOW_CTX_DAG_OWNER='***' AIRFLOW_CTX_DAG_ID='branching_example' AIRFLOW_CTX_TASK_ID='generate_random_number' AIRFLOW_CTX_EXECUTION_DATE='2023-09-16T04:50:32.158743+00:00' AIRFLOW_CTX_TRY_NUMBER='1' AIRFLOW_CTX_DAG_RUN_ID='manual__2023-09-16T04:50:32.158743+00:00'
[2023-09-16T04:50:33.222+0000] {taskinstance.py:1935} ERROR - Task failed with exception
Traceback (most recent call last):
  File "/home/airflow/.local/lib/python3.8/site-packages/airflow/operators/python.py", line 192, in execute
    return_value = self.execute_callable()
  File "/home/airflow/.local/lib/python3.8/site-packages/airflow/operators/python.py", line 209, in execute_callable
    return self.python_callable(*self.op_args, **self.op_kwargs)
TypeError: separate_even_and_odd() missing 1 required positional argument: 'number'
[2023-09-16T04:50:33.227+0000] {taskinstance.py:1398} INFO - Marking task as FAILED. dag_id=branching_example, task_id=generate_random_number, execution_date=20230916T045032, start_date=20230916T045033, end_date=20230916T045033
[2023-09-16T04:50:33.237+0000] {standard_task_runner.py:104} ERROR - Failed to execute job 57 for task generate_random_number (separate_even_and_odd() missing 1 required positional argument: 'number'; 1900)
[2023-09-16T04:50:33.270+0000] {local_task_job_runner.py:228} INFO - Task exited with return code 1
[2023-09-16T04:50:33.286+0000] {taskinstance.py:2776} INFO - 0 downstream tasks scheduled from follow-on schedule check
